..XX...X..XXX.X.....
XXX.....X..X...X....
.....X...XXX.XX.....
.XXXXXXX...XXXXX

Failed tests:

✖ sync fail todo (0.5888ms) # TODO
  Error: thrown from sync fail todo
      *
      *
      *
      *
      *
      *
      *
✖ sync fail todo with message (0.2438ms) # this is a failing todo
  Error: thrown from sync fail todo with message
      *
      *
      *
      *
      *
      *
      *
✖ sync throw fail (0.2247ms)
  Error: thrown from sync throw fail
      *
      *
      *
      *
      *
      *
      *
✖ async throw fail (1.0176ms)
  Error: thrown from async throw fail
      *
      *
      *
      *
      *
      *
      *
﹣ async skip fail (0.343ms) # SKIP
  Error: thrown from async throw fail
      *
      *
      *
      *
      *
      *
      *
✖ async assertion fail (2.7152ms)
  AssertionError [ERR_ASSERTION]: Expected values to be strictly equal:
  
  true !== false
  
      *
      *
      *
      *
      *
      *
      * {
    generatedMessage: true,
    code: 'ERR_ASSERTION',
    actual: true,
    expected: false,
    operator: 'strictEqual'
  }
✖ reject fail (0.3434ms)
  Error: rejected from reject fail
      *
      *
      *
      *
      *
      *
      *
  ✖ +sync throw fail (0.2289ms)
    Error: thrown from subtest sync throw fail
        *
        *
        *
        *
        *
        *
        *
        *
        *
        *
✖ subtest sync throw fail (0.6737ms)
  '1 subtest failed'
✖ sync throw non-error fail (0.3685ms)
  Symbol(thrown symbol from sync throw non-error fail)
  ✖ +long running (1.4232ms)
    'test did not finish before its parent and was cancelled'
✖ top level (1.3747ms)
  '1 subtest failed'
✖ sync skip option is false fail (0.2162ms)
  Error: this should be executed
      *
      *
      *
      *
      *
      *
      *
✖ callback fail (0.632ms)
  Error: callback failure
      *
      *
✖ callback also returns a Promise (0.2499ms)
  'passed a callback but also returned a Promise'
✖ callback throw (0.2055ms)
  Error: thrown from callback throw
      *
      *
      *
      *
      *
      *
      *
✖ callback called twice (0.1711ms)
  'callback invoked multiple times'
✖ callback called twice in future tick (2.9922ms)
  Error [ERR_TEST_FAILURE]: callback invoked multiple times
      * {
    code: 'ERR_TEST_FAILURE',
    failureType: 'multipleCallbackInvocations',
    cause: 'callback invoked multiple times'
  }
✖ callback async throw (0.7809ms)
  Error: thrown from callback async throw
      *
      *
✖ custom inspect symbol fail (0.5309ms)
  customized
✖ custom inspect symbol that throws fail (2.4636ms)
  { foo: 1, [Symbol(nodejs.util.inspect.custom)]: [Function: [nodejs.util.inspect.custom]] }
  ✖ sync throw fails at first (0.1774ms)
    Error: thrown from subtest sync throw fails at first
        *
        *
        *
        *
        *
        *
        *
        *
        *
        *
  ✖ sync throw fails at second (0.1261ms)
    Error: thrown from subtest sync throw fails at second
        *
        *
        *
        *
        *
        *
        *
        *
✖ subtest sync throw fails (0.6118ms)
  '2 subtests failed'
✖ timed out async test (14.7614ms)
  'test timed out after 5ms'
✖ timed out callback test (17.1008ms)
  'test timed out after 5ms'
✖ rejected thenable (0.2498ms)
  'custom error'
✖ unfinished test with uncaughtException (1.3337ms)
  Error: foo
      *
      *
      *
✖ unfinished test with unhandledRejection (1.0768ms)
  Error: bar
      *
      *
      *
✖ assertion errors display actual and expected properly (17.7021ms)
  AssertionError [ERR_ASSERTION]: Expected values to be loosely deep-equal:
  
  {
    bar: 1,
    baz: {
      date: 1970-01-01T00:00:00.000Z,
      null: null,
      number: 1,
      string: 'Hello',
      undefined: undefined
    },
    boo: [
      1
    ],
    foo: 1
  }
  
  should loosely deep-equal
  
  {
    baz: {
      date: 1970-01-01T00:00:00.000Z,
      null: null,
      number: 1,
      string: 'Hello',
      undefined: undefined
    },
    boo: [
      1
    ],
    circular: <ref *1> {
      bar: 2,
      c: [Circular *1]
    }
  }
      * {
    generatedMessage: true,
    code: 'ERR_ASSERTION',
    actual: [Object],
    expected: [Object],
    operator: 'deepEqual'
  }
✖ invalid subtest fail (0.8032ms)
  'test could not be started because its parent finished'
